Workbook
Name CRF: #REF!
Name DiscountRate: #REF!
Name FacilityLifetime: #REF!
Name GeneralDataManufacturingLocations: #REF!
Name MaterialData316SSStandardDensity: #REF!
Name MaterialDataA36CSStandardDensity: #REF!
Name MaterialDataB4CNaturalTheoreticalDensity: #REF!
Name MaterialDataConcreteNominalSolidDensity: #REF!
Name MaterialDataGeneralInsulationStandardDensity: #REF!
Name MaterialDataGR22StandardDensity: #REF!
Name MaterialDataInconel718StandardDensity: #REF!
Name UC_m_in: #REF!

Sheet Cost Database
A1: Account | B1: Level | C1: Account Name | D1: Account Title | E1: Standard Cost Equation? | F1: Optional Variable | G1: Optional Value | H1: Sec Optional Variable | I1: Sec Optional Value | J1: Fixed Cost ($) | K1: Unit Cost | L1: Unit Cost (units) | M1: Scaling Variable | N1: Scaling Variable Ref Value | O1: Units | P1: Exponent | Q1: Dollar Year | R1: Type | S1: Source | T1: Ref | U1: Link | V1: Notes | W1: FOAK to NOAK Multiplier Type | X1: Fixed Cost Low End | Y1: Fixed Cost High End | Z1: Fixed Cost Distribution | AA1: Unit Cost Low End | AB1: Unit Cost High End | AC1: Unit Cost Distribution | AD1: Exponent std | AE1: Exponent Max | AF1: Exponent Min | AG1: Exponent Distribution
A2: 10 | B2: =IF(ISNUMBER(A2), IF(AND(A2=INT(A2), MOD(A2, 10) = 0), 0, IF(AND(A2=INT(A2), LEN(A2)=2), 1, IF(AND(A2=INT(A2), LEN(A2)=3), 2, LEN(A2) - FIND(".", A2) + 2) ) ), "") -> 0 | C2: Capitalized Pre-Construction Costs | D2: =REPT(" ", B2*2) & C2 -> Capitalized Pre-Construction Costs
A3: 11 | B3: =IF(ISNUMBER(A3), IF(AND(A3=INT(A3), MOD(A3, 10) = 0), 0, IF(AND(A3=INT(A3), LEN(A3)=2), 1, IF(AND(A3=INT(A3), LEN(A3)=3), 2, LEN(A3) - FIND(".", A3) + 2) ) ), "") -> 1 | C3: Land Cost | D3: =REPT(" ", B3*2) & C3 -> Land Cost | E3: standard | K3: 3800 | L3: $/acres | M3: Land Area | O3: acres | Q3: 2022 | R3: General | S3: The average cost per acre for rural land in 2022 from the US Department of Agriculture | T3: Abou-Jaoude, A., Lohse, C. S., Larsen, L. M., Guaita, N., Trivedi, I., Joseck, F. C., ... & Stein, A. (2024). Meta-analysis of advanced nuclear reactor cost estimations (No. INL/RPT-24-77048-Rev001). Idaho National Laboratory (INL), Idaho Falls, ID (United States). | U3: https://inldigitallibrary.inl.gov/sites/sti/sti/Sort_107010.pdf | W3: No Learning | X3: =0.9*$J3 -> 0 | Y3: =1.5*J3 -> 0 | Z3: Lognormal | AA3: =0.9*K3 -> 3420 | AB3: =1.3*K3 -> 4940 | AC3: Lognormal | AD3: 0.1 | AE3: 1 | AF3: 0 | AG3: Truncated Normal
A4: 12 | B4: =IF(ISNUMBER(A4), IF(AND(A4=INT(A4), MOD(A4, 10) = 0), 0, IF(AND(A4=INT(A4), LEN(A4)=2), 1, IF(AND(A4=INT(A4), LEN(A4)=3), 2, LEN(A4) - FIND(".", A4) + 2) ) ), "") -> 1 | C4: Site Permits | D4: =REPT(" ", B4*2) & C4 -> Site Permits | E4: standard | K4: =10.03*1000 -> 10030 | L4: $/MWe | M4: Power MWe | O4: MWe | Q4: 2022 | R4: Labor | S4: Data from SMR MHTGRs | W4: No Learning | X4: =0.9*$J4 -> 0 | Y4: =1.5*J4 -> 0 | Z4: Lognormal | AA4: =0.9*K4 -> 9027 | AB4: =1.3*K4 -> 13039 | AC4: Lognormal | AD4: 0.1 | AE4: 1 | AF4: 0 | AG4: Truncated Normal
A5: 13 | B5: =IF(ISNUMBER(A5), IF(AND(A5=INT(A5), MOD(A5, 10) = 0), 0, IF(AND(A5=INT(A5), LEN(A5)=2), 1, IF(AND(A5=INT(A5), LEN(A5)=3), 2, LEN(A5) - FIND(".", A5) + 2) ) ), "") -> 1 | C5: Plant Licensing | D5: =REPT(" ", B5*2) & C5 -> Plant Licensing | E5: standard | J5: =0.5*(X5+Y5) -> 28113008 | Q5: 2025 | R5: Labor | S5: NRC Website | T5: According to NRC, the number of hours range from 108K to 257K hours https://www.nrc.gov/docs/ML2301/ML23018A174.pdf For the hourly rate: 154$/hour https://www.federalregister.gov/documents/2026/06/16/2026-12067/fee-schedules-fee-recovery-for-fiscal-year-2026 | U5: https://art.inl.gov/NGNP/INL%20Documents/Year%202012/Assessment%20of%20High%20Temperature%20Gas-Cooled%20Reactor%20-%20HTGR%20-%20Capital%20and%20Operating%20Costs.pdf | W5: Licensing Learning | X5: =154*108000 -> 16632000 | Y5: =154*257104 -> 39594016 | Z5: Uniform | AA5: =0.9*K5 -> 0 | AB5: =1.3*K5 -> 0 | AC5: Lognormal | AD5: 0.1 | AE5: 1 | AF5: 0 | AG5: Truncated Normal
A6: 14 | B6: =IF(ISNUMBER(A6), IF(AND(A6=INT(A6), MOD(A6, 10) = 0), 0, IF(AND(A6=INT(A6), LEN(A6)=2), 1, IF(AND(A6=INT(A6), LEN(A6)=3), 2, LEN(A6) - FIND(".", A6) + 2) ) ), "") -> 1 | C6: Plant Permits | D6: =REPT(" ", B6*2) & C6 -> Plant Permits | E6: standard | J6: 3000000 | Q6: 2009 | R6: Labor | S6: NGNP project | T6: Gandrik, A., B. Wallace, L. Demick, S. Melancon and M. Patterson (2011). "Assessment of high temperature gas-cooled reactor (HTGR) capital and operating costs." Idaho National Laboratory, TEV-1196, Idaho Falls, ID. | W6: No Learning | X6: =0.9*$J6 -> 2700000 | Y6: =1.5*J6 -> 4500000 | Z6: Lognormal | AA6: =0.9*K6 -> 0 | AB6: =1.3*K6 -> 0 | AC6: Lognormal | AD6: 0.1 | AE6: 1 | AF6: 0 | AG6: Truncated Normal
A7: 15 | B7: =IF(ISNUMBER(A7), IF(AND(A7=INT(A7), MOD(A7, 10) = 0), 0, IF(AND(A7=INT(A7), LEN(A7)=2), 1, IF(AND(A7=INT(A7), LEN(A7)=3), 2, LEN(A7) - FIND(".", A7) + 2) ) ), "") -> 1 | C7: Plant Studies | D7: =REPT(" ", B7*2) & C7 -> Plant Studies | E7: standard | J7: =MARVEL_Cost!C4 -> 5210451 | Q7: 2024 | R7: Labor | S7: MARVEL Project (Labor-adjusted Cost) | T7: Hanna, B. N., Gonzaga de Oliveira, R. G., Mohammad Al Dawood, K. A., Patterson, M. D., Abou Jaoude, A., & Garcia, S. (2024). Technoeconomic Evaluation of Microreactor Using Detailed Bottom-up Estimate (No. INL/RPT-24-80433-Rev000). Idaho National Laboratory (INL), Idaho Falls, ID (United States). | U7: https://inldigitallibrary.inl.gov/sites/sti/sti/Sort_129862.pdf | V7: MARVEL's data were updated | W7: No Learning | X7: =0.9*$J7 -> 4689405.9 | Y7: =1.5*J7 -> 7815676.5 | Z7: Lognormal | AA7: =0.9*K7 -> 0 | AB7: =1.3*K7 -> 0 | AC7: Lognormal | AD7: 0.1 | AE7: 1 | AF7: 0 | AG7: Truncated Normal
A8: 20 | B8: =IF(ISNUMBER(A8), IF(AND(A8=INT(A8), MOD(A8, 10) = 0), 0, IF(AND(A8=INT(A8), LEN(A8)=2), 1, IF(AND(A8=INT(A8), LEN(A8)=3), 2, LEN(A8) - FIND(".", A8) + 2) ) ), "") -> 0 | C8: Capitalized Direct Costs | D8: =REPT(" ", B8*2) & C8 -> Capitalized Direct Costs
A9: 21 | B9: =IF(ISNUMBER(A9), IF(AND(A9=INT(A9), MOD(A9, 10) = 0), 0, IF(AND(A9=INT(A9), LEN(A9)=2), 1, IF(AND(A9=INT(A9), LEN(A9)=3), 2, LEN(A9) - FIND(".", A9) + 2) ) ), "") -> 1 | C9: Structures and Improvements | D9: =REPT(" ", B9*2) & C9 -> Structures and Improvements
A10: 211 | B10: =IF(ISNUMBER(A10), IF(AND(A10=INT(A10), MOD(A10, 10) = 0), 0, IF(AND(A10=INT(A10), LEN(A10)=2), 1, IF(AND(A10=INT(A10), LEN(A10)=3), 2, LEN(A10) - FIND(".", A10) + 2) ) ), "") -> 2 | C10: Site Preparation/ Yard Work | D10: =REPT(" ", B10*2) & C10 -> Site Preparation/ Yard Work
A11: 211.1 | B11: =IF(ISNUMBER(A11), IF(AND(A11=INT(A11), MOD(A11, 10) = 0), 0, IF(AND(A11=INT(A11), LEN(A11)=2), 1, IF(AND(A11=INT(A11), LEN(A11)=3), 2, LEN(A11) - FIND(".", A11) + 2) ) ), "") -> 3 | C11: Cleaning and Grubbing | D11: =REPT(" ", B11*2) & C11 -> Cleaning and Grubbing | E11: standard | K11: =4408.18*1.33 -> 5862.8794 | L11: $/acres | M11: Land Area | O11: acres | Q11: 2024 | R11: Lab and Equip | S11: RSMeans software: a tool that primarily provides costs for non-nuclear work Nuclear Multiplier have been applied to adjust the costs for nuclear-site-related work | T11: GORDIAN. (2024). "RSMeans data. & Delene, J. G. and I. Hudson, C. R. (1993). Cost estimate guidelines for advanced nuclear power technologies. United States, Oak Ridge National Lab. (ORNL), Oak Ridge, TN (United States): Medium: ED; Size: 159 p. | U11: https://www.rsmeans.com/ & https://www.osti.gov/biblio/10176857 | W11: Onsite Learning | X11: =0.9*$J11 -> 0 | Y11: =1.5*J11 -> 0 | Z11: Lognormal | AA11: =0.9*K11 -> 5276.5915 | AB11: =1.3*K11 -> 7621.7432 | AC11: Lognormal | AD11: 0.1 | AE11: 1 | AF11: 0 | AG11: Truncated Normal
A12: 211.2 | B12: =IF(ISNUMBER(A12), IF(AND(A12=INT(A12), MOD(A12, 10) = 0), 0, IF(AND(A12=INT(A12), LEN(A12)=2), 1, IF(AND(A12=INT(A12), LEN(A12)=3), 2, LEN(A12) - FIND(".", A12) + 2) ) ), "") -> 3 | C12: Stripping Topsoil | D12: =REPT(" ", B12*2) & C12 -> Stripping Topsoil | E12: standard | K12: =2565.2*1.33 -> 3411.716 | L12: $/acres | M12: Land Area | O12: acres | Q12: 2024 | R12: Lab and Equip | W12: Onsite Learning | X12: =0.9*$J12 -> 0 | Y12: =1.5*J12 -> 0 | Z12: Lognormal | AA12: =0.9*K12 -> 3070.5444 | AB12: =1.3*K12 -> 4435.2308 | AC12: Lognormal | AD12: 0.1 | AE12: 1 | AF12: 0 | AG12: Truncated Normal
A13: 211.3 | B13: =IF(ISNUMBER(A13), IF(AND(A13=INT(A13), MOD(A13, 10) = 0), 0, IF(AND(A13=INT(A13), LEN(A13)=2), 1, IF(AND(A13=INT(A13), LEN(A13)=3), 2, LEN(A13) - FIND(".", A13) + 2) ) ), "") -> 3 | C13: Excavation | D13: =REPT(" ", B13*2) & C13 -> Excavation | E13: standard | K13: =22.86*1.4 -> 32.004 | L13: $/m^3 | M13: Excavation Volume | O13: m^3 | Q13: 2024 | R13: Lab and Equip | W13: Onsite Learning | X13: =0.9*$J13 -> 0 | Y13: =1.5*J13 -> 0 | Z13: Lognormal | AA13: =0.9*K13 -> 28.8036 | AB13: =1.3*K13 -> 41.6052 | AC13: Lognormal | AD13: 0.1 | AE13: 1 | AF13: 0 | AG13: Truncated Normal
A14: 211.4 | B14: =IF(ISNUMBER(A14), IF(AND(A14=INT(A14), MOD(A14, 10) = 0), 0, IF(AND(A14=INT(A14), LEN(A14)=2), 1, IF(AND(A14=INT(A14), LEN(A14)=3), 2, LEN(A14) - FIND(".", A14) + 2) ) ), "") -> 3 | C14: Roads | D14: =REPT(" ", B14*2) & C14 -> Roads | E14: standard | K14: =0.7*7873200*1.609/1000 -> 8867.5852 | L14: $/m | M14: GEN Road Length | O14: m | Q14: 2025 | R14: General | S14: MC30 Cost Estimation of Microreactor Facilities Inital Draft 5-6-2026.pdf, less 30% | W14: Onsite Learning | X14: =0.9*$J14 -> 0 | Y14: =1.5*J14 -> 0 | Z14: Lognormal | AA14: =0.9*K14 -> 7980.8266 | AB14: =1.3*K14 -> 11527.861 | AC14: Lognormal | AD14: 0.1 | AE14: 1 | AF14: 0 | AG14: Truncated Normal
A15: 211.9 | B15: =IF(ISNUMBER(A15), IF(AND(A15=INT(A15), MOD(A15, 10) = 0), 0, IF(AND(A15=INT(A15), LEN(A15)=2), 1, IF(AND(A15=INT(A15), LEN(A15)=3), 2, LEN(A15) - FIND(".", A15) + 2) ) ), "") -> 3 | C15: Security Fencing | D15: =REPT(" ", B15*2) & C15 -> Security Fencing
A16: 211.91 | B16: =IF(ISNUMBER(A16), IF(AND(A16=INT(A16), MOD(A16, 10) = 0), 0, IF(AND(A16=INT(A16), LEN(A16)=2), 1, IF(AND(A16=INT(A16), LEN(A16)=3), 2, LEN(A16) - FIND(".", A16) + 2) ) ), "") -> 4 | C16: Security Fencing Limited | D16: =REPT(" ", B16*2) & C16 -> Security Fencing Limited | E16: standard | K16: =0.7*273.38*3.2808 -> 627.83357 | L16: $/m | M16: Limited Perimeter | O16: m | Q16: 2025 | R16: General | S16: MC30 Cost Estimation of Microreactor Facilities Inital Draft 5-6-2026.pdf, less 30% | W16: Onsite Learning | X16: =0.9*$J16 -> 0 | Y16: =1.5*J16 -> 0 | Z16: Lognormal | AA16: =0.9*K16 -> 565.05022 | AB16: =1.3*K16 -> 816.18364 | AC16: Lognormal | AD16: 0.1 | AE16: 1 | AF16: 0 | AG16: Truncated Normal
A17: 211.93 | B17: =IF(ISNUMBER(A17), IF(AND(A17=INT(A17), MOD(A17, 10) = 0), 0, IF(AND(A17=INT(A17), LEN(A17)=2), 1, IF(AND(A17=INT(A17), LEN(A17)=3), 2, LEN(A17) - FIND(".", A17) + 2) ) ), "") -> 4 | C17: Security Fencing Protected | D17: =REPT(" ", B17*2) & C17 -> Security Fencing Protected | E17: standard | K17: =0.7*15183.17*3.2808 -> 34869.061 | L17: $/m | M17: Protected Perimeter | O17: m | Q17: 2025 | R17: General | S17: MC30 Cost Estimation of Microreactor Facilities Inital Draft 5-6-2026.pdf, less 30% | W17: Onsite Learning | X17: =0.9*$J17 -> 0 | Y17: =1.5*J17 -> 0 | Z17: Lognormal | AA17: =0.9*K17 -> 31382.155 | AB17: =1.3*K17 -> 45329.779 | AC17: Lognormal | AD17: 0.1 | AE17: 1 | AF17: 0 | AG17: Truncated Normal
A18: 212 | B18: =IF(ISNUMBER(A18), IF(AND(A18=INT(A18), MOD(A18, 10) = 0), 0, IF(AND(A18=INT(A18), LEN(A18)=2), 1, IF(AND(A18=INT(A18), LEN(A18)=3), 2, LEN(A18) - FIND(".", A18) + 2) ) ), "") -> 2 | C18: Reactor Island Civil Structures | D18: =REPT(" ", B18*2) & C18 -> Reactor Island Civil Structures
A19: 212.1 | B19: =IF(ISNUMBER(A19), IF(AND(A19=INT(A19), MOD(A19, 10) = 0), 0, IF(AND(A19=INT(A19), LEN(A19)=2), 1, IF(AND(A19=INT(A19), LEN(A19)=3), 2, LEN(A19) - FIND(".", A19) + 2) ) ), "") -> 3 | C19: Reactor Building Slab Roof | D19: =REPT(" ", B19*2) & C19 -> Reactor Building Slab Roof | E19: standard | K19: =1200 *1.53 -> 1836 | L19: $/m^3 | M19: Reactor Building Slab Roof Volume | O19: m^3 | Q19: 2024 | R19: Lab and Mat and Equip | S19: RSMeans software: a tool that primarily provides costs for non-nuclear work Nuclear Multiplier have been applied to adjust the costs for nuclear-site-related work | T19: GORDIAN. (2024). "RSMeans data. & Delene, J. G. and I. Hudson, C. R. (1993). Cost estimate guidelines for advanced nuclear power technologies. United States, Oak Ridge National Lab. (ORNL), Oak Ridge, TN (United States): Medium: ED; Size: 159 p. | U19: https://www.rsmeans.com/ & https://www.osti.gov/biblio/10176857 | W19: Onsite Learning | X19: =0.9*$J19 -> 0 | Y19: =1.5*J19 -> 0 | Z19: Lognormal | AA19: =0.9*K19 -> 1652.4 | AB19: =1.3*K19 -> 2386.8 | AC19: Lognormal | AD19: 0.1 | AE19: 1 | AF19: 0 | AG19: Truncated Normal
A20: 212.2 | B20: =IF(ISNUMBER(A20), IF(AND(A20=INT(A20), MOD(A20, 10) = 0), 0, IF(AND(A20=INT(A20), LEN(A20)=2), 1, IF(AND(A20=INT(A20), LEN(A20)=3), 2, LEN(A20) - FIND(".", A20) + 2) ) ), "") -> 3 | C20: Reactor Building Basement | D20: =REPT(" ", B20*2) & C20 -> Reactor Building Basement | E20: standard | K20: =943.9*1.53 -> 1444.167 | L20: $/m^3 | M20: Reactor Building Basement Volume | O20: m^3 | Q20: 2024 | R20: Lab and Mat and Equip | W20: Onsite Learning | X20: =0.9*$J20 -> 0 | Y20: =1.5*J20 -> 0 | Z20: Lognormal | AA20: =0.9*K20 -> 1299.7503 | AB20: =1.3*K20 -> 1877.4171 | AC20: Lognormal | AD20: 0.1 | AE20: 1 | AF20: 0 | AG20: Truncated Normal
A21: 212.3 | B21: =IF(ISNUMBER(A21), IF(AND(A21=INT(A21), MOD(A21, 10) = 0), 0, IF(AND(A21=INT(A21), LEN(A21)=2), 1, IF(AND(A21=INT(A21), LEN(A21)=3), 2, LEN(A21) - FIND(".", A21) + 2) ) ), "") -> 3 | C21: Reactor Building Walls | D21: =REPT(" ", B21*2) & C21 -> Reactor Building Walls | E21: standard | K21: =721.21*1.53 -> 1103.4513 | L21: $/m^3 | M21: Reactor Building Exterior Walls Volume | O21: m^3 | Q21: 2024 | R21: Lab and Mat and Equip | W21: Onsite Learning | X21: =0.9*$J21 -> 0 | Y21: =1.5*J21 -> 0 | Z21: Lognormal | AA21: =0.9*K21 -> 993.10617 | AB21: =1.3*K21 -> 1434.4867 | AC21: Lognormal | AD21: 0.1 | AE21: 1 | AF21: 0 | AG21: Truncated Normal
A22: 212.4 | B22: =IF(ISNUMBER(A22), IF(AND(A22=INT(A22), MOD(A22, 10) = 0), 0, IF(AND(A22=INT(A22), LEN(A22)=2), 1, IF(AND(A22=INT(A22), LEN(A22)=3), 2, LEN(A22) - FIND(".", A22) + 2) ) ), "") -> 3 | C22: Reactor Building Liner | D22: =REPT(" ", B22*2) & C22 -> Reactor Building Liner | E22: standard | K22: =60848829/9373 -> 6491.9267 | L22: $/m^2 | M22: Reactor Building Superstructure Area | N22: 9373 | O22: m^2 | P22: 1 | Q22: 2018 | R22: Lab and Mat and Equip | S22: Stewart W.R., Shirvan K., "Capital cost estimation for advanced nuclear power plants," Renewable and Sustainable Energy Reviews, Nov. 2021, 111880 | T22: Stewart W.R., Shirvan K., "Capital cost estimation for advanced nuclear power plants," Renewable and Sustainable Energy Reviews, Nov. 2021, 111880 | U22: https://doi.org/10.1016/j.rser.2021.111880 | W22: Onsite Learning | X22: =0.9*$J22 -> 0 | Y22: =1.5*J22 -> 0 | Z22: Lognormal | AA22: =0.9*K22 -> 5842.734 | AB22: =1.3*K22 -> 8439.5047 | AC22: Lognormal | AD22: 0.1 | AE22: 1 | AF22: 0 | AG22: Truncated Normal
A23: 212.5 | B23: =IF(ISNUMBER(A23), IF(AND(A23=INT(A23), MOD(A23, 10) = 0), 0, IF(AND(A23=INT(A23), LEN(A23)=2), 1, IF(AND(A23=INT(A23), LEN(A23)=3), 2, LEN(A23) - FIND(".", A23) + 2) ) ), "") -> 3 | C23: Reactor Building HVAC | D23: =REPT(" ", B23*2) & C23 -> Reactor Building HVAC | E23: standard | K23: =5917967/N23 -> 1731.9189 | L23: $/MWt | M23: Power MWt | N23: 3417 | O23: MWt | P23: 0.8 | Q23: 2018 | R23: Lab and Mat and Equip | S23: Stewart W.R., Shirvan K., "Capital cost estimation for advanced nuclear power plants," Renewable and Sustainable Energy Reviews, Nov. 2021, 111880 | T23: Stewart W.R., Shirvan K., "Capital cost estimation for advanced nuclear power plants," Renewable and Sustainable Energy Reviews, Nov. 2021, 111880 | U23: https://doi.org/10.1016/j.rser.2021.111880 | W23: Onsite Learning | X23: =0.9*$J23 -> 0 | Y23: =1.5*J23 -> 0 | Z23: Lognormal | AA23: =0.9*K23 -> 1558.727 | AB23: =1.3*K23 -> 2251.4946 | AC23: Lognormal | AD23: 0.1 | AE23: 1 | AF23: 0 | AG23: Truncated Normal
A24: 213 | B24: =IF(ISNUMBER(A24), IF(AND(A24=INT(A24), MOD(A24, 10) = 0), 0, IF(AND(A24=INT(A24), LEN(A24)=2), 1, IF(AND(A24=INT(A24), LEN(A24)=3), 2, LEN(A24) - FIND(".", A24) + 2) ) ), "") -> 2 | C24: Main Function Buildings | D24: =REPT(" ", B24*2) & C24 -> Main Function Buildings
A25: 213.1 | B25: =IF(ISNUMBER(A25), IF(AND(A25=INT(A25), MOD(A25, 10) = 0), 0, IF(AND(A25=INT(A25), LEN(A25)=2), 1, IF(AND(A25=INT(A25), LEN(A25)=3), 2, LEN(A25) - FIND(".", A25) + 2) ) ), "") -> 3 | C25: Energy conversion Building | D25: =REPT(" ", B25*2) & C25 -> Energy conversion Building
A26: 213.11 | B26: =IF(ISNUMBER(A26), IF(AND(A26=INT(A26), MOD(A26, 10) = 0), 0, IF(AND(A26=INT(A26), LEN(A26)=2), 1, IF(AND(A26=INT(A26), LEN(A26)=3), 2, LEN(A26) - FIND(".", A26) + 2) ) ), "") -> 4 | C26: Energy Conversion Building Slab Roof | D26: =REPT(" ", B26*2) & C26 -> Energy Conversion Building Slab Roof | E26: standard | K26: =1200 -> 1200 | L26: $/m^3 | M26: Turbine Building Slab Roof Volume | O26: m^3 | Q26: 2024 | R26: Lab and Mat and Equip | S26: RSMeans software: a tool that primarily provides costs for non-nuclear work | T26: GORDIAN. (2024). "RSMeans data. & Delene, J. G. and I. Hudson, C. R. (1993). Cost estimate guidelines for advanced nuclear power technologies. United States, Oak Ridge National Lab. (ORNL), Oak Ridge, TN (United States): Medium: ED; Size: 159 p. | U26: https://www.rsmeans.com/ & https://www.osti.gov/biblio/10176857 | W26: Onsite Learning | X26: =0.9*$J26 -> 0 | Y26: =1.5*J26 -> 0 | Z26: Lognormal | AA26: =0.9*K26 -> 1080 | AB26: =1.3*K26 -> 1560 | AC26: Lognormal | AD26: 0.1 | AE26: 1 | AF26: 0 | AG26: Truncated Normal
A27: 213.12 | B27: =IF(ISNUMBER(A27), IF(AND(A27=INT(A27), MOD(A27, 10) = 0), 0, IF(AND(A27=INT(A27), LEN(A27)=2), 1, IF(AND(A27=INT(A27), LEN(A27)=3), 2, LEN(A27) - FIND(".", A27) + 2) ) ), "") -> 4 | C27: Energy Conversion Building Basement | D27: =REPT(" ", B27*2) & C27 -> Energy Conversion Building Basement | E27: standard | K27: =943.9 -> 943.9 | L27: $/m^3 | M27: Turbine Building Basement Volume | O27: m^3 | Q27: 2024 | R27: Lab and Mat and Equip | W27: Onsite Learning | X27: =0.9*$J27 -> 0 | Y27: =1.5*J27 -> 0 | Z27: Lognormal | AA27: =0.9*K27 -> 849.51 | AB27: =1.3*K27 -> 1227.07 | AC27: Lognormal | AD27: 0.1 | AE27: 1 | AF27: 0 | AG27: Truncated Normal
A28: 213.13 | B28: =IF(ISNUMBER(A28), IF(AND(A28=INT(A28), MOD(A28, 10) = 0), 0, IF(AND(A28=INT(A28), LEN(A28)=2), 1, IF(AND(A28=INT(A28), LEN(A28)=3), 2, LEN(A28) - FIND(".", A28) + 2) ) ), "") -> 4 | C28: Energy Conversion Building Walls | D28: =REPT(" ", B28*2) & C28 -> Energy Conversion Building Walls | E28: standard | K28: =721.21 -> 721.21 | L28: $/m^3 | M28: Turbine Building Exterior Walls Volume | O28: m^3 | Q28: 2024 | R28: Lab and Mat and Equip | W28: Onsite Learning | X28: =0.9*$J28 -> 0 | Y28: =1.5*J28 -> 0 | Z28: Lognormal | AA28: =0.9*K28 -> 649.089 | AB28: =1.3*K28 -> 937.573 | AC28: Lognormal | AD28: 0.1 | AE28: 1 | AF28: 0 | AG28: Truncated Normal
A29: 213.2 | B29: =IF(ISNUMBER(A29), IF(AND(A29=INT(A29), MOD(A29, 10) = 0), 0, IF(AND(A29=INT(A29), LEN(A29)=2), 1, IF(AND(A29=INT(A29), LEN(A29)=3), 2, LEN(A29) - FIND(".", A29) + 2) ) ), "") -> 3 | C29: Control building | D29: =REPT(" ", B29*2) & C29 -> Control building
A30: 213.21 | B30: =IF(ISNUMBER(A30), IF(AND(A30=INT(A30), MOD(A30, 10) = 0), 0, IF(AND(A30=INT(A30), LEN(A30)=2), 1, IF(AND(A30=INT(A30), LEN(A30)=3), 2, LEN(A30) - FIND(".", A30) + 2) ) ), "") -> 4 | C30: Control Building Slab Roof | D30: =REPT(" ", B30*2) & C30 -> Control Building Slab Roof | E30: standard | K30: =1200 -> 1200 | L30: $/m^3 | M30: Control Building Slab Roof Volume | O30: m^3 | Q30: 2024 | R30: Lab and Mat and Equip | S30: RSMeans software: a tool that primarily provides costs for non-nuclear work | T30: GORDIAN. (2024). "RSMeans data. & Delene, J. G. and I. Hudson, C. R. (1993). Cost estimate guidelines for advanced nuclear power technologies. United States, Oak Ridge National Lab. (ORNL), Oak Ridge, TN (United States): Medium: ED; Size: 159 p. | U30: https://www.rsmeans.com/ & https://www.osti.gov/biblio/10176857 | W30: Onsite Learning | X30: =0.9*$J30 -> 0 | Y30: =1.5*J30 -> 0 | Z30: Lognormal | AA30: =0.9*K30 -> 1080 | AB30: =1.3*K30 -> 1560 | AC30: Lognormal | AD30: 0.1 | AE30: 1 | AF30: 0 | AG30: Truncated Normal
A31: 213.22 | B31: =IF(ISNUMBER(A31), IF(AND(A31=INT(A31), MOD(A31, 10) = 0), 0, IF(AND(A31=INT(A31), LEN(A31)=2), 1, IF(AND(A31=INT(A31), LEN(A31)=3), 2, LEN(A31) - FIND(".", A31) + 2) ) ), "") -> 4 | C31: Control Building Basement | D31: =REPT(" ", B31*2) & C31 -> Control Building Basement | E31: standard | K31: =943.9 -> 943.9 | L31: $/m^3 | M31: Control Building Basement Volume | O31: m^3 | Q31: 2024 | R31: Lab and Mat and Equip | W31: Onsite Learning | X31: =0.9*$J31 -> 0 | Y31: =1.5*J31 -> 0 | Z31: Lognormal | AA31: =0.9*K31 -> 849.51 | AB31: =1.3*K31 -> 1227.07 | AC31: Lognormal | AD31: 0.1 | AE31: 1 | AF31: 0 | AG31: Truncated Normal
A32: 213.23 | B32: =IF(ISNUMBER(A32), IF(AND(A32=INT(A32), MOD(A32, 10) = 0), 0, IF(AND(A32=INT(A32), LEN(A32)=2), 1, IF(AND(A32=INT(A32), LEN(A32)=3), 2, LEN(A32) - FIND(".", A32) + 2) ) ), "") -> 4 | C32: Control Building Walls | D32: =REPT(" ", B32*2) & C32 -> Control Building Walls | E32: standard | K32: =721.21 -> 721.21 | L32: $/m^3 | M32: Control Building Exterior Walls Volume | O32: m^3 | Q32: 2024 | R32: Lab and Mat and Equip | W32: Onsite Learning | X32: =0.9*$J32 -> 0 | Y32: =1.5*J32 -> 0 | Z32: Lognormal | AA32: =0.9*K32 -> 649.089 | AB32: =1.3*K32 -> 937.573 | AC32: Lognormal | AD32: 0.1 | AE32: 1 | AF32: 0 | AG32: Truncated Normal
A33: 213.3 | B33: =IF(ISNUMBER(A33), IF(AND(A33=INT(A33), MOD(A33, 10) = 0), 0, IF(AND(A33=INT(A33), LEN(A33)=2), 1, IF(AND(A33=INT(A33), LEN(A33)=3), 2, LEN(A33) - FIND(".", A33) + 2) ) ), "") -> 3 | C33: Integrated Heat Exchanger Building | D33: =REPT(" ", B33*2) & C33 -> Integrated Heat Exchanger Building | F33: reactor type | G33: GCMR
A34: 213.31 | B34: =IF(ISNUMBER(A34), IF(AND(A34=INT(A34), MOD(A34, 10) = 0), 0, IF(AND(A34=INT(A34), LEN(A34)=2), 1, IF(AND(A34=INT(A34), LEN(A34)=3), 2, LEN(A34) - FIND(".", A34) + 2) ) ), "") -> 4 | C34: Integrated Heat Exchanger Building Slab Roof | D34: =REPT(" ", B34*2) & C34 -> Integrated Heat Exchanger Building Slab Roof | E34: standard | F34: reactor type | G34: GCMR | K34: =1200 -> 1200 | L34: $/m^3 | M34: Integrated Heat Exchanger Building Slab Roof Volume | O34: m^3 | Q34: 2024 | R34: Lab and Mat and Equip | S34: RSMeans software: a tool that primarily provides costs for non-nuclear work | T34: GORDIAN. (2024). "RSMeans data. & Delene, J. G. and I. Hudson, C. R. (1993). Cost estimate guidelines for advanced nuclear power technologies. United States, Oak Ridge National Lab. (ORNL), Oak Ridge, TN (United States): Medium: ED; Size: 159 p. | U34: https://www.rsmeans.com/ & https://www.osti.gov/biblio/10176857 | W34: Onsite Learning | X34: =0.9*$J34 -> 0 | Y34: =1.5*J34 -> 0 | Z34: Lognormal | AA34: =0.9*K34 -> 1080 | AB34: =1.3*K34 -> 1560 | AC34: Lognormal | AD34: 0.1 | AE34: 1 | AF34: 0 | AG34: Truncated Normal
A35: 213.32 | B35: =IF(ISNUMBER(A35), IF(AND(A35=INT(A35), MOD(A35, 10) = 0), 0, IF(AND(A35=INT(A35), LEN(A35)=2), 1, IF(AND(A35=INT(A35), LEN(A35)=3), 2, LEN(A35) - FIND(".", A35) + 2) ) ), "") -> 4 | C35: Integrated Heat Exchanger Building Basement | D35: =REPT(" ", B35*2) & C35 -> Integrated Heat Exchanger Building Basement | E35: standard | F35: reactor type | G35: GCMR | K35: =943.9 -> 943.9 | L35: $/m^3 | M35: Integrated Heat Exchanger Building Basement Volume | O35: m^3 | Q35: 2024 | R35: Lab and Mat and Equip | W35: Onsite Learning | X35: =0.9*$J35 -> 0 | Y35: =1.5*J35 -> 0 | Z35: Lognormal | AA35: =0.9*K35 -> 849.51 | AB35: =1.3*K35 -> 1227.07 | AC35: Lognormal | AD35: 0.1 | AE35: 1 | AF35: 0 | AG35: Truncated Normal
A36: 213.33 | B36: =IF(ISNUMBER(A36), IF(AND(A36=INT(A36), MOD(A36, 10) = 0), 0, IF(AND(A36=INT(A36), LEN(A36)=2), 1, IF(AND(A36=INT(A36), LEN(A36)=3), 2, LEN(A36) - FIND(".", A36) + 2) ) ), "") -> 4 | C36: Integrated Heat Exchanger Building Walls | D36: =REPT(" ", B36*2) & C36 -> Integrated Heat Exchanger Building Walls | E36: standard | F36: reactor type | G36: GCMR | K36: =721.21 -> 721.21 | L36: $/m^3 | M36: Integrated Heat Exchanger Building Exterior Walls Volume | O36: m^3 | Q36: 2024 | R36: Lab and Mat and Equip | W36: Onsite Learning | X36: =0.9*$J36 -> 0 | Y36: =1.5*J36 -> 0 | Z36: Lognormal | AA36: =0.9*K36 -> 649.089 | AB36: =1.3*K36 -> 937.573 | AC36: Lognormal | AD36: 0.1 | AE36: 1 | AF36: 0 | AG36: Truncated Normal
A37: 213.34 | B37: =IF(ISNUMBER(A37), IF(AND(A37=INT(A37), MOD(A37, 10) = 0), 0, IF(AND(A37=INT(A37), LEN(A37)=2), 1, IF(AND(A37=INT(A37), LEN(A37)=3), 2, LEN(A37) - FIND(".", A37) + 2) ) ), "") -> 4 | C37: Integrated Heat Exchanger Building Liner | D37: =REPT(" ", B37*2) & C37 -> Integrated Heat Exchanger Building Liner | E37: standard | F37: reactor type | G37: GCMR | K37: =60848829/9373 -> 6491.9267 | L37: $/m^2 | M37: Integrated Heat Exchanger Building Superstructure Area | N37: 9373 | O37: m^2 | P37: 1 | Q37: 2018 | R37: Lab and Mat and Equip | S37: Stewart W.R., Shirvan K., "Capital cost estimation for advanced nuclear power plants," Renewable and Sustainable Energy Reviews, Nov. 2021, 111880 | T37: Stewart W.R., Shirvan K., "Capital cost estimation for advanced nuclear power plants," Renewable and Sustainable Energy Reviews, Nov. 2021, 111880 | U37: https://doi.org/10.1016/j.rser.2021.111880 | W37: Onsite Learning | X37: =0.9*$J37 -> 0 | Y37: =1.5*J37 -> 0 | Z37: Lognormal | AA37: =0.9*K37 -> 5842.734 | AB37: =1.3*K37 -> 8439.5047 | AC37: Lognormal | AD37: 0.1 | AE37: 1 | AF37: 0 | AG37: Truncated Normal
A38: 214 | B38: =IF(ISNUMBER(A38), IF(AND(A38=INT(A38), MOD(A38, 10) = 0), 0, IF(AND(A38=INT(A38), LEN(A38)=2), 1, IF(AND(A38=INT(A38), LEN(A38)=3), 2, LEN(A38) - FIND(".", A38) + 2) ) ), "") -> 2 | C38: Buildings to Support Main Function | D38: =REPT(" ", B38*2) & C38 -> Buildings to Support Main Function
A39: 214.1 | B39: =IF(ISNUMBER(A39), IF(AND(A39=INT(A39), MOD(A39, 10) = 0), 0, IF(AND(A39=INT(A39), LEN(A39)=2), 1, IF(AND(A39=INT(A39), LEN(A39)=3), 2, LEN(A39) - FIND(".", A39) + 2) ) ), "") -> 3 | C39: Fuel Management Buildings | D39: =REPT(" ", B39*2) & C39 -> Fuel Management Buildings
A40: 214.11 | B40: =IF(ISNUMBER(A40), IF(AND(A40=INT(A40), MOD(A40, 10) = 0), 0, IF(AND(A40=INT(A40), LEN(A40)=2), 1, IF(AND(A40=INT(A40), LEN(A40)=3), 2, LEN(A40) - FIND(".", A40) + 2) ) ), "") -> 4 | C40: Refueling Building | D40: =REPT(" ", B40*2) & C40 -> Refueling Building
...

Sheet MARVEL_Cost
A1: Account ID | B1: Account Title | C1: TOTAL COST (2024 USD)
A3: 10 | B3: Capitalized Pre-Construction Costs | C3: =C4 -> 5210451
A4: 15 | B4: Plant Studies | C4: 5210451
A5: 20 | B5: Capitalized Direct Costs | C5: =C6+C13+C45+C48+C52+C54 -> 30295715
A6: 21 | B6: Structures and Improvements | C6: =C7+C8+C9+C10 -> 2799006.7
A7: 211 | B7: Site Preparation/Yard Work
A8: 212 | B8: Reactor Island Civil Structures | C8: 2573469.9
A9: 213 | B9: Main Function Buildings
A10: 214 | B10: Buildings to Support Main Function | C10: =SUM(C11) -> 225536.86
A11: 214.7 | B11: Emergency and Start-up Power Systems | C11: 225536.86
A12: 217 | B12: Miscellaneous Other Structures
A13: 22 | B13: Reactor System | C13: =C14+C32+C41+C42+C43+C44 -> 17586713
A14: 221 | B14: Reactor Components | C14: =C15+C19+C25 -> 8937296.6
A15: 221.1 | B15: Reactor vessel and accessories | C15: =C16+C17+C18 -> 2004852
A16: 221.11 | B16: Reactor support | C16: 762382.4
A17: 221.12 | B17: Outer vessel structure | C17: 1201688.6
A18: 221.13 | B18: Inner vessel structure | C18: 40781
A19: 221.2 | B19: Reactor control devices | C19: =C20 -> 2114223
A20: 221.21 | B20: Reactivity control system | C20: =SUM(C21:C23) -> 2114223
A21: 221.211 | B21: Reactivity Control System Fabrication | C21: 1391560
A22: 221.212 | B22: Installation | C22: 322663
A23: 221.213 | B23: Control Drums Materials (Absorber) | C23: 400000
A24: 221.214 | B24: Control Drums Materials (Reflector)
A25: 221.3 | B25: Non-fuel core internals | C25: =C26+C30+C31 -> 4818221.6
A26: 221.31 | B26: Reflector | C26: 4170231
A27: 221.311 | B27: Reflector (Materials: BeO) | C27: 3200000
A28: 221.312 | B28: Reflector (Materials: Be Metal) | C28: 850000
A29: 221.313 | B29: Reflector (installation | C29: 120231
A30: 221.32 | B30: Shield | C30: 647990.6
A31: 221.33 | B31: Moderator | C31: 0
A32: 222 | B32: Main Heat Transport System | C32: =C33+C34+C38+C39+C40 -> 5908950.6
A33: 222.1 | B33: Fluid circulation drive system | C33: 0
A34: 222.2 | B34: Reactor Heat Hransfer Piping System | C34: 4890230.6
A35: 222.21 | B35: Reactor Heat Hransfer Piping System (Mat) | C35: 1520786
A36: 222.22 | B36: Reactor Heat Hransfer Piping System (Fabrication) | C36: 3341486
A37: 222.23 | B37: Reactor Heat Hransfer Piping System (Installation) | C37: 27958.6
A38: 222.3 | B38: Heat Exchangers | C38: 0
A39: 222.4 | B39: Pressurizer System | C39: 0
A40: 222.5 | B40: Initial Heat Transfer Fluid Inventory | C40: 1018720
A41: 224 | B41: Radioactive Byproduct Processing Systems
...

Sheet Design Variables
A1: Variable | B1: Value | C1: Units | D1: Description
A2: Overall System
A3: Thermal power | B3: 83 | C3: kWth | D3: —
A4: Electric Power | B4: 20 | C4: kWe
A5: Core outer radius | B5: 5.5 | C5: inches | D5: —
A6: Reflector outer radius | B6: 16.5 | C6: inches | D6: —
A7: Fuel
A8: Fuel mass | B8: 145.3 | C8: kg | D8: UZrH
A9: U Weight fraction | B9: 30 | C9: wt% | D9: U/UZrH
A10: U enrichment | B10: 19.75 | C10: wt% | D10: High-assay low-enriched uranium (HALEU)
A11: Pins | B11: 36 | C11: # | D11: —
A12: Reflector
A13: Outer reflector material | B13: BeO | C13: — | D13: 99% theoretical density
A14: Elements | B14: 124 | C14: # | D14: Quarter plates
A15: Reflector plate thickness | B15: 1 | C15: inches | D15: —
A16: Reflector plate volume | B16: 818.4 | C16: cm3/plate | D16: —
A17: Mass of BeO reflector | B17: 318 | C17: Kg
A18: Insert volume | B18: 570 | C18: cm3/plate | D18: —
A19: Mass of Be-metal reflector | B19: 0.019 | C19: MT | D19: —
A20: Control Elements
A21: Control drums | B21: 4 | C21: # | D21: —
A22: Shutdown rods | B22: 1 | C22: # | D22: —
A23: Control drum elements | B23: 124 | C23: # | D23: Discs
A24: Drum disc thickness | B24: 1 | C24: inches | D24: —
A25: Drum reflector volume | B25: 880.8 | C25: cm3/plate | D25: BeO 99%
A26: Mass of drum reflector | B26: 309 | C26: Kg | D26: —
A27: Drum poison volume | B27: 49.2 | C27: cm3/plate | D27: B4C
A28: Mass of drum poison | B28: 14 | C28: Kg | D28: —
A29: Mass of rod poison | B29: 14 | C29: Kg | D29: B4C
A30: Instruments and Controls
A31: Control cabinet | B31: 5 | D31: —
A32: Instrument cabinet | B32: 2 | D32: —
A33: Nuclear input/output (IO) | B33: 9 | D33: —
A34: Non-nuclear IO | B34: 213 | D34: —
A35: Stirling engine IO | B35: 48 | C35: — | D35: These should be excluded if there no stirling engine?
A36: TOTAL | B36: 277
A37: Shielding in Vessel
A38: Stainless Steel cans | B38: 54.2 | C38: Kg | D38: Stainless Steel cans of the boron carbide shielding material (SS316H)
A39: Gamma shield material | B39: 56.3 | C39: Kg | D39: Gamma shield material inside the guard vessel (of Tungsten)
A40: Neutron shield material in the guard vessel | B40: 39.7 | C40: Kg | D40: made of natural B4C powder and is located above the core (a donut around the core barrel)—
...

Sheet Inflation Adjustment
A1: Year | B1: General | C1: Labor | D1: Material | E1: Equipment | F1: Lab and Mat and Equip | G1: Lab and Equip
A2: 1978 | B2: 3.1209 | C2: 4.2536 | D2: 3.811 | E2: 5.3954 | F2: =(C2+D2+E2)/3 -> 4.4866667 | G2: =AVERAGE(C2,E2) -> 4.8245
A3: 1985 | B3: 2.53801 | C3: 3.3122863 | D3: 3.1461261 | E3: 4.0603969 | F3: =(C3+D3+E3)/3 -> 3.5062697 | G3: =AVERAGE(C3,E3) -> 3.6863416
A4: 1986 | B4: 2.4877976 | C4: 3.2086278 | D4: 3.1524765 | E4: 3.957082 | F4: =(C4+D4+E4)/3 -> 3.4393954 | G4: =AVERAGE(C4,E4) -> 3.5828549
A5: 1987 | B5: 2.4278243 | C5: 3.1112605 | D5: 3.0891631 | E5: 3.9210211 | F5: =(C5+D5+E5)/3 -> 3.3738149 | G5: =AVERAGE(C5,E5) -> 3.5161408
A6: 1988 | B6: 2.3451469 | C6: 2.989825 | D6: 2.9257907 | E6: 3.7360352 | F6: =(C6+D6+E6)/3 -> 3.217217 | G6: =AVERAGE(C6,E6) -> 3.3629301
A7: 1989 | B7: 2.2565183 | C7: 2.8925 | D7: 2.8323254 | E7: 3.5114259 | F7: =(C7+D7+E7)/3 -> 3.0787504 | G7: =AVERAGE(C7,E7) -> 3.2019629
A8: 1990 | B8: 2.1749312 | C8: 2.765278 | D8: 2.828971 | E8: 3.4175276 | F8: =(C8+D8+E8)/3 -> 3.0039255 | G8: =AVERAGE(C8,E8) -> 3.0914028
A9: 1991 | B9: 2.103917 | C9: 2.6561658 | D9: 2.8109546 | E9: 3.3052946 | F9: =(C9+D9+E9)/3 -> 2.9241383 | G9: =AVERAGE(C9,E9) -> 2.9807302
A10: 1992 | B10: 2.0570925 | C10: 2.5740904 | D10: 2.7621964 | E10: 3.1693577 | F10: =(C10+D10+E10)/3 -> 2.8352148 | G10: =AVERAGE(C10,E10) -> 2.871724
A11: 1993 | B11: 2.0094227 | C11: 2.4922663 | D11: 2.6313537 | E11: 2.9935069 | F11: =(C11+D11+E11)/3 -> 2.7057089 | G11: =AVERAGE(C11,E11) -> 2.7428866
A12: 1994 | B12: 1.967432 | C12: 2.4032889 | D12: 2.528144 | E12: 2.9062257 | F12: =(C12+D12+E12)/3 -> 2.6125529 | G12: =AVERAGE(C12,E12) -> 2.6547573
A13: 1995 | B13: 1.9269732 | C13: 2.3615592 | D13: 2.4372516 | E13: 2.8565425 | F13: =(C13+D13+E13)/3 -> 2.5517845 | G13: =AVERAGE(C13,E13) -> 2.6090509
... A43: 2025 | B43: 1 | C43: 1 | D43: 1 | E43: 1 | F43: =(C43+D43+E43)/3 -> 1 | G43: =AVERAGE(C43,E43) -> 1

Sheet Economics Parameters
A1: Parameter | B1: Value | C1: Note | D1: Reference | E1: Notes
A2: indirect to direct field-related cost | B2: 0.065389932
A3: FTEs Per Onsite Operator (24/7) | B3: 5
A4: FTEs Per Offsite Operator (24/7) | B4: 5
A5: FTEs Per Security Staff (24/7) | B5: 5
A6: Hours Per FTE | B6: 1800
A7: Work Hours Per Shift | B7: 10
A8: Maintenance to Direct Cost Ratio | B8: 0.03
A9: Onsite Learning | B9: 0.08 | C9: FOAK to NOAK Learning Rates | D9: Assessment of Factory Fabrication Considerations for Nuclear Microreactors 10.1080/00295450.2023.2206779 | E9: Calculated based on Refernce Paper + Gyutae's work. Refer to TEM Slides for rationale and methodology
A10: No Learning | B10: 0
A11: Licensing Learning | B11: 0.2 | C11: Nth of a kind licening was estimated to take 30-42 months https://www.nrc.gov/docs/ML2426/ML24268A310.pdf Now, it is estimated to take 6- 12 months https://www.govinfo.gov/content/pkg/FR-2026-05-01/pdf/2026-08550.pdf Therefor, the cost is estimated to be reduced 4 times (a factor of 0.25). Since MOUSE is using learning rates, this factor is converted to a learning rate of 0.2 assuming 100 units
A12: Factory Primary Structure | B12: 0.1844317 | C12: FOAK to NOAK Learning Rates
A13: Factory Drums | B13: 0.24138 | C13: FOAK to NOAK Learning Rates
A14: Factory Other | B14: 0.22962848 | C14: FOAK to NOAK Learning Rates
A15: Factory Be | B15: 0.41505378 | C15: FOAK to NOAK Learning Rates
A16: Factory BeO | B16: 0.39914906 | C16: FOAK to NOAK Learning Rates
A17: Non-nuclear off-the-shelf | B17: 0.05 | D17: Park, et al., Bottom-up levelized cost estimation of low-enriched and low-pressure nuclear batteries. Nuclear Engineering and Design. 2025. | E17: For off-the-shelf commercial components that are not produced in the FB Factory
A18: SER Account 30 to Account 20 Ratio | B18: 0.5 | E18: Account 30 is 50% of direct cost (Account 20).
A19: SER Account 716 to Accounts 711-715 Ratio | B19: 0.02 | E19: Continuing education and retraining.
A20: SER Account 717 to Accounts 711-715 Ratio | B20: 0.075 | E20: Management staff.
A21: SER Account 741 to Account 20 Ratio | B21: 0.005 | E21: Operating chemicals and lubricants.
A22: SER Account 742 to Account 20 Ratio | B22: 0.05 | E22: Spare parts.
A23: SER Account 743 to Account 20 Ratio | B23: 0.01 | E23: Utilities excluding electricity, supplies, and consumables.
A24: SER Account 747.1 to Accounts 741-743 Ratio | B24: 0.05 | E24: Annualized transportation costs.
A25: SER Account 747.4 to Account 20 Ratio | B25: 0.005 | E25: Annualized other supplies and utilities.
A26: MFG Account 223 to Reactor OCC per Testing Line Ratio | B26: 0.1 | E26: REVIEW NEEDED: provisional testing-building assumption.
A27: MFG Account 30 to Account 20 Ratio | B27: 0.5 | E27: Account 30 is 50% of direct cost.
A28: MFG Account 716 to Accounts 711-715 Ratio | B28: 0.02 | E28: Continuing education and retraining.
A29: MFG Account 717 to Accounts 711-715 Ratio | B29: 0.075 | E29: Management staff.
... A34: MFG Account 747.4 to Account 20 Ratio | B34: 0.005 | E34: Annualized other supplies and utilities.

Sheet Manufacturing Campus Database
A1: Account | B1: Level | C1: Account Name | D1: Account Title | E1: Standard Cost Equation? | F1: Count Scaling Variable | G1: Count per Variable | H1: Optional Variable | I1: Optional Value | J1: Fixed Cost ($) | K1: Unit Cost | L1: Unit Cost (units) | M1: Scaling Variable | N1: Scaling Variable Ref Value | O1: Units | P1: Exponent | Q1: Dollar Year | R1: Type | S1: Source | T1: Ref | U1: Link | V1: Notes | W1: FOAK to NOAK Multiplier Type | X1: Fixed Cost Low End | Y1: Fixed Cost High End | Z1: Fixed Cost Distribution | AA1: Unit Cost Low End | AB1: Unit Cost High End | AC1: Unit Cost Distribution | AD1: Exponent std | AE1: Exponent Max | AF1: Exponent Min | AG1: Exponent Distribution
A2: 10 | B2: =IF(ISNUMBER(A2), IF(AND(A2=INT(A2), MOD(A2, 10) = 0), 0, IF(AND(A2=INT(A2), LEN(A2)=2), 1, IF(AND(A2=INT(A2), LEN(A2)=3), 2, LEN(A2) - FIND(".", A2) + 2) ) ), "") -> 0 | C2: Capitalized Pre-Construction Costs | D2: =REPT(" ", B2*2) & C2 -> Capitalized Pre-Construction Costs
A3: 11 | B3: =IF(ISNUMBER(A3), IF(AND(A3=INT(A3), MOD(A3, 10) = 0), 0, IF(AND(A3=INT(A3), LEN(A3)=2), 1, IF(AND(A3=INT(A3), LEN(A3)=3), 2, LEN(A3) - FIND(".", A3) + 2) ) ), "") -> 1 | C3: Land Cost | D3: =REPT(" ", B3*2) & C3 -> Land Cost | E3: standard | F3: Constant | G3: 1 | K3: 3800 | L3: $/acres | M3: MFG Campus Land Area | O3: acres | Q3: 2022 | R3: General | S3: The average cost per acre for rural land in 2022 from the US Department of Agriculture | T3: Abou-Jaoude, A., Lohse, C. S., Larsen, L. M., Guaita, N., Trivedi, I., Joseck, F. C., ... & Stein, A. (2024). Meta-analysis of advanced nuclear reactor cost estimations (No. INL/RPT-24-77048-Rev001). Idaho National Laboratory (INL), Idaho Falls, ID (United States). | U3: https://inldigitallibrary.inl.gov/sites/sti/sti/Sort_107010.pdf | W3: No Learning | X3: =0.9*$J3 -> 0 | Y3: =1.5*J3 -> 0 | Z3: Lognormal | AA3: =0.9*K3 -> 3420 | AB3: =1.3*K3 -> 4940 | AC3: Lognormal | AD3: 0.1 | AE3: 1 | AF3: 0 | AG3: Truncated Normal
A4: 12 | B4: =IF(ISNUMBER(A4), IF(AND(A4=INT(A4), MOD(A4, 10) = 0), 0, IF(AND(A4=INT(A4), LEN(A4)=2), 1, IF(AND(A4=INT(A4), LEN(A4)=3), 2, LEN(A4) - FIND(".", A4) + 2) ) ), "") -> 1 | C4: Site Permits | D4: =REPT(" ", B4*2) & C4 -> Site Permits | E4: standard | F4: Constant | G4: 1 | K4: =10.03*1000 -> 10030 | L4: $/MWe | M4: MFG Campus Power | O4: MWe | Q4: 2022 | R4: Labor | S4: Data from SMR MHTGRs | W4: No Learning | X4: =0.9*$J4 -> 0 | Y4: =1.5*J4 -> 0 | Z4: Lognormal | AA4: =0.9*K4 -> 9027 | AB4: =1.3*K4 -> 13039 | AC4: Lognormal | AD4: 0.1 | AE4: 1 | AF4: 0 | AG4: Truncated Normal
A5: 13 | B5: =IF(ISNUMBER(A5), IF(AND(A5=INT(A5), MOD(A5, 10) = 0), 0, IF(AND(A5=INT(A5), LEN(A5)=2), 1, IF(AND(A5=INT(A5), LEN(A5)=3), 2, LEN(A5) - FIND(".", A5) + 2) ) ), "") -> 1 | C5: Plant Licensing | D5: =REPT(" ", B5*2) & C5 -> Plant Licensing | E5: standard | F5: Constant | G5: 1 | J5: =1000000*45 -> 45000000 | Q5: 2009 | R5: Labor | S5: NGNP project | T5: Gandrik, A., B. Wallace, L. Demick, S. Melancon and M. Patterson (2011). "Assessment of high temperature gas-cooled reactor (HTGR) capital and operating costs." Idaho National Laboratory, TEV-1196, Idaho Falls, ID. | U5: https://art.inl.gov/NGNP/INL%20Documents/Year%202012/Assessment%20of%20High%20Temperature%20Gas-Cooled%20Reactor%20-%20HTGR%20-%20Capital%20and%20Operating%20Costs.pdf | W5: No Learning | X5: =45*1000000 -> 45000000 | Y5: =70*1000000 -> 70000000 | Z5: Uniform | AA5: =0.9*K5 -> 0 | AB5: =1.3*K5 -> 0 | AC5: Lognormal | AD5: 0.1 | AE5: 1 | AF5: 0 | AG5: Truncated Normal
A6: 14 | B6: =IF(ISNUMBER(A6), IF(AND(A6=INT(A6), MOD(A6, 10) = 0), 0, IF(AND(A6=INT(A6), LEN(A6)=2), 1, IF(AND(A6=INT(A6), LEN(A6)=3), 2, LEN(A6) - FIND(".", A6) + 2) ) ), "") -> 1 | C6: Plant Permits | D6: =REPT(" ", B6*2) & C6 -> Plant Permits | E6: standard | F6: Constant | G6: 1 | J6: 3000000 | Q6: 2009 | R6: Labor | S6: NGNP project | W6: No Learning | X6: =0.9*$J6 -> 2700000 | Y6: =1.5*J6 -> 4500000 | Z6: Lognormal | AA6: =0.9*K6 -> 0 | AB6: =1.3*K6 -> 0 | AC6: Lognormal | AD6: 0.1 | AE6: 1 | AF6: 0 | AG6: Truncated Normal
A7: 15 | B7: =IF(ISNUMBER(A7), IF(AND(A7=INT(A7), MOD(A7, 10) = 0), 0, IF(AND(A7=INT(A7), LEN(A7)=2), 1, IF(AND(A7=INT(A7), LEN(A7)=3), 2, LEN(A7) - FIND(".", A7) + 2) ) ), "") -> 1 | C7: Plant Studies | D7: =REPT(" ", B7*2) & C7 -> Plant Studies | E7: standard | F7: Constant | G7: 1 | J7: =10*MARVEL_Cost!C4 -> 52104510 | Q7: 2024 | R7: Labor | S7: MARVEL Project (Labor-adjusted Cost) | T7: Hanna, B. N., Gonzaga de Oliveira, R. G., Mohammad Al Dawood, K. A., Patterson, M. D., Abou Jaoude, A., & Garcia, S. (2024). Technoeconomic Evaluation of Microreactor Using Detailed Bottom-up Estimate (No. INL/RPT-24-80433-Rev000). Idaho National Laboratory (INL), Idaho Falls, ID (United States). | U7: https://inldigitallibrary.inl.gov/sites/sti/sti/Sort_129862.pdf | V7: MARVEL's data were updated | W7: No Learning | X7: =0.9*$J7 -> 46894059 | Y7: =1.5*J7 -> 78156765 | Z7: Lognormal | AA7: =0.9*K7 -> 0 | AB7: =1.3*K7 -> 0 | AC7: Lognormal | AD7: 0.1 | AE7: 1 | AF7: 0 | AG7: Truncated Normal
A8: 20 | B8: =IF(ISNUMBER(A8), IF(AND(A8=INT(A8), MOD(A8, 10) = 0), 0, IF(AND(A8=INT(A8), LEN(A8)=2), 1, IF(AND(A8=INT(A8), LEN(A8)=3), 2, LEN(A8) - FIND(".", A8) + 2) ) ), "") -> 0 | C8: Capitalized Direct Costs | D8: =REPT(" ", B8*2) & C8 -> Capitalized Direct Costs | W8: 598
A9: 21 | B9: =IF(ISNUMBER(A9), IF(AND(A9=INT(A9), MOD(A9, 10) = 0), 0, IF(AND(A9=INT(A9), LEN(A9)=2), 1, IF(AND(A9=INT(A9), LEN(A9)=3), 2, LEN(A9) - FIND(".", A9) + 2) ) ), "") -> 1 | C9: Structures and Improvements | D9: =REPT(" ", B9*2) & C9 -> Structures and Improvements
A10: 211 | B10: =IF(ISNUMBER(A10), IF(AND(A10=INT(A10), MOD(A10, 10) = 0), 0, IF(AND(A10=INT(A10), LEN(A10)=2), 1, IF(AND(A10=INT(A10), LEN(A10)=3), 2, LEN(A10) - FIND(".", A10) + 2) ) ), "") -> 2 | C10: Site Preparation/ Yard Work | D10: =REPT(" ", B10*2) & C10 -> Site Preparation/ Yard Work
A11: 211.1 | B11: =IF(ISNUMBER(A11), IF(AND(A11=INT(A11), MOD(A11, 10) = 0), 0, IF(AND(A11=INT(A11), LEN(A11)=2), 1, IF(AND(A11=INT(A11), LEN(A11)=3), 2, LEN(A11) - FIND(".", A11) + 2) ) ), "") -> 3 | C11: Cleaning and Grubbing | D11: =REPT(" ", B11*2) & C11 -> Cleaning and Grubbing | E11: standard | F11: Constant | G11: 1 | K11: =4408.18*1.33 -> 5862.8794 | L11: $/acres | M11: MFG Campus Land Area | O11: acres | Q11: 2024 | R11: Lab and Equip | S11: RSMeans software: a tool that primarily provides costs for non-nuclear work Nuclear Multiplier have been applied to adjust the costs for nuclear-site-related work | T11: GORDIAN. (2024). "RSMeans data. & Delene, J. G. and I. Hudson, C. R. (1993). Cost estimate guidelines for advanced nuclear power technologies. United States, Oak Ridge National Lab. (ORNL), Oak Ridge, TN (United States): Medium: ED; Size: 159 p. | U11: https://www.rsmeans.com/ & https://www.osti.gov/biblio/10176857 | W11: No Learning | X11: =0.9*$J11 -> 0 | Y11: =1.5*J11 -> 0 | Z11: Lognormal | AA11: =0.9*K11 -> 5276.5915 | AB11: =1.3*K11 -> 7621.7432 | AC11: Lognormal | AD11: 0.1 | AE11: 1 | AF11: 0 | AG11: Truncated Normal
A12: 211.2 | B12: =IF(ISNUMBER(A12), IF(AND(A12=INT(A12), MOD(A12, 10) = 0), 0, IF(AND(A12=INT(A12), LEN(A12)=2), 1, IF(AND(A12=INT(A12), LEN(A12)=3), 2, LEN(A12) - FIND(".", A12) + 2) ) ), "") -> 3 | C12: Stripping Topsoil | D12: =REPT(" ", B12*2) & C12 -> Stripping Topsoil | E12: standard | F12: Constant | G12: 1 | K12: =2565.2*1.33 -> 3411.716 | L12: $/acres | M12: MFG Campus Land Area | O12: acres | Q12: 2024 | R12: Lab and Equip | W12: No Learning | X12: =0.9*$J12 -> 0 | Y12: =1.5*J12 -> 0 | Z12: Lognormal | AA12: =0.9*K12 -> 3070.5444 | AB12: =1.3*K12 -> 4435.2308 | AC12: Lognormal | AD12: 0.1 | AE12: 1 | AF12: 0 | AG12: Truncated Normal
A13: 211.4 | B13: =IF(ISNUMBER(A13), IF(AND(A13=INT(A13), MOD(A13, 10) = 0), 0, IF(AND(A13=INT(A13), LEN(A13)=2), 1, IF(AND(A13=INT(A13), LEN(A13)=3), 2, LEN(A13) - FIND(".", A13) + 2) ) ), "") -> 3 | C13: Roads | D13: =REPT(" ", B13*2) & C13 -> Roads | E13: standard | F13: Constant | G13: 1 | K13: =0.7*7873200*1.609/1000 -> 8867.5852 | L13: $/m | M13: MFG Road Length | N13: 1 | P13: 1 | Q13: 2025 | R13: General | S13: MC30 Cost Estimation of Microreactor Facilities Inital Draft 5-6-2026.pdf, less 30% | W13: No Learning | X13: =0.9*$J13 -> 0 | Y13: =1.5*J13 -> 0 | Z13: Lognormal | AA13: =0.9*K13 -> 7980.8266 | AB13: =1.3*K13 -> 11527.861 | AC13: Lognormal | AD13: 0.1 | AE13: 1 | AF13: 0 | AG13: Truncated Normal
A14: 211.9 | B14: =IF(ISNUMBER(A14), IF(AND(A14=INT(A14), MOD(A14, 10) = 0), 0, IF(AND(A14=INT(A14), LEN(A14)=2), 1, IF(AND(A14=INT(A14), LEN(A14)=3), 2, LEN(A14) - FIND(".", A14) + 2) ) ), "") -> 3 | C14: Security Fencing | D14: =REPT(" ", B14*2) & C14 -> Security Fencing
A15: 211.91 | B15: =IF(ISNUMBER(A15), IF(AND(A15=INT(A15), MOD(A15, 10) = 0), 0, IF(AND(A15=INT(A15), LEN(A15)=2), 1, IF(AND(A15=INT(A15), LEN(A15)=3), 2, LEN(A15) - FIND(".", A15) + 2) ) ), "") -> 4 | C15: Security Fencing Limited | D15: =REPT(" ", B15*2) & C15 -> Security Fencing Limited | E15: standard | F15: Constant | G15: 1 | K15: =0.7*273 -> 191.1 | L15: $/ft | M15: MFG Site Perimeter | Q15: 2025 | R15: Lab and Equip | S15: MC30 Cost Estimation of Microreactor Facilities Inital Draft 5-6-2026.pdf, less 30% | W15: No Learning | X15: =0.9*$J15 -> 0 | Y15: =1.5*J15 -> 0 | Z15: Lognormal | AA15: =0.9*K15 -> 171.99 | AB15: =1.3*K15 -> 248.43 | AC15: Lognormal | AD15: 0.1 | AE15: 1 | AF15: 0 | AG15: Truncated Normal
A16: 211.93 | B16: =IF(ISNUMBER(A16), IF(AND(A16=INT(A16), MOD(A16, 10) = 0), 0, IF(AND(A16=INT(A16), LEN(A16)=2), 1, IF(AND(A16=INT(A16), LEN(A16)=3), 2, LEN(A16) - FIND(".", A16) + 2) ) ), "") -> 4 | C16: Security Fencing Protected | D16: =REPT(" ", B16*2) & C16 -> Security Fencing Protected | E16: standard | F16: Constant | G16: 1 | K16: =0.7*15746 -> 11022.2 | L16: $/ft | M16: MFG Protected Perimeter | Q16: 2025 | R16: Lab and Equip | S16: MC30 Cost Estimation of Microreactor Facilities Inital Draft 5-6-2026.pdf, less 30% | W16: No Learning | X16: =0.9*$J16 -> 0 | Y16: =1.5*J16 -> 0 | Z16: Lognormal | AA16: =0.9*K16 -> 9919.98 | AB16: =1.3*K16 -> 14328.86 | AC16: Lognormal | AD16: 0.1 | AE16: 1 | AF16: 0 | AG16: Truncated Normal
A17: 214 | B17: =IF(ISNUMBER(A17), IF(AND(A17=INT(A17), MOD(A17, 10) = 0), 0, IF(AND(A17=INT(A17), LEN(A17)=2), 1, IF(AND(A17=INT(A17), LEN(A17)=3), 2, LEN(A17) - FIND(".", A17) + 2) ) ), "") -> 2 | C17: Servicing Facilities Structures | D17: =REPT(" ", B17*2) & C17 -> Servicing Facilities Structures
A18: 214.3 | B18: =IF(ISNUMBER(A18), IF(AND(A18=INT(A18), MOD(A18, 10) = 0), 0, IF(AND(A18=INT(A18), LEN(A18)=2), 1, IF(AND(A18=INT(A18), LEN(A18)=3), 2, LEN(A18) - FIND(".", A18) + 2) ) ), "") -> 3 | C18: Control Buidlings | D18: =REPT(" ", B18*2) & C18 -> Control Buidlings
A19: 214.31 | B19: 4 | C19: Local Control Buidling Structure | D19: =REPT(" ", B19*2) & C19 -> Local Control Buidling Structure | E19: standard | F19: Constant | G19: 1 | K19: =0.7*2653*(3.2808^2) -> 19989.172 | L19: $/m^2 | M19: MFG Local Control Building Area | N19: 1 | O19: m^2 | P19: 1 | Q19: 2025 | R19: Lab and Mat and Equip | S19: 100 value from MC30 Cost Estimation of Microreactor Facilities Inital Draft 5-6-2026.pdf, less 30% [temporary, want to add scaling equation] | W19: No Learning | X19: =0.9*$I19 -> 0 | Y19: =1.5*J19 -> 0 | Z19: Lognormal | AA19: =0.9*K19 -> 17990.255 | AB19: =1.3*K19 -> 25985.923 | AC19: Lognormal | AD19: 0.1 | AE19: 1 | AF19: 0 | AG19: Truncated Normal
A20: 22 | B20: =IF(ISNUMBER(A20), IF(AND(A20=INT(A20), MOD(A20, 10) = 0), 0, IF(AND(A20=INT(A20), LEN(A20)=2), 1, IF(AND(A20=INT(A20), LEN(A20)=3), 2, LEN(A20) - FIND(".", A20) + 2) ) ), "") -> 1 | C20: Main Facilities Estimated As Wholes | D20: =REPT(" ", B20*2) & C20 -> Main Facilities Estimated As Wholes
A21: 221 | B21: =IF(ISNUMBER(A21), IF(AND(A21=INT(A21), MOD(A21, 10) = 0), 0, IF(AND(A21=INT(A21), LEN(A21)=2), 1, IF(AND(A21=INT(A21), LEN(A21)=3), 2, LEN(A21) - FIND(".", A21) + 2) ) ), "") -> 2 | C21: Manufacturing Building | D21: =REPT(" ", B21*2) & C21 -> Manufacturing Building | E21: standard | K21: =62733028.09/N21 -> 62733.028 | M21: Production Rate | N21: 1000 | O21: Rx/yr | P21: 0.13827065 | Q21: 2025 | R21: Lab and Mat and Equip | W21: No Learning | X21: =0.9*$I21 -> 0 | Y21: =1.5*J21 -> 0 | Z21: Lognormal | AA21: =0.9*K21 -> 56459.725 | AB21: =1.3*K21 -> 81552.937 | AC21: Lognormal | AD21: 0.1 | AE21: 1 | AF21: 0 | AG21: Truncated Normal
A22: 222 | B22: =IF(ISNUMBER(A22), IF(AND(A22=INT(A22), MOD(A22, 10) = 0), 0, IF(AND(A22=INT(A22), LEN(A22)=2), 1, IF(AND(A22=INT(A22), LEN(A22)=3), 2, LEN(A22) - FIND(".", A22) + 2) ) ), "") -> 2 | C22: Fueling Building | D22: =REPT(" ", B22*2) & C22 -> Fueling Building | E22: standard | K22: =35766971.91/N22 -> 35766.972 | M22: Production Rate | N22: 1000 | O22: Rx/yr | P22: 0.13827065 | Q22: 2025 | R22: Lab and Mat and Equip | W22: No Learning | X22: =0.9*$I22 -> 0 | Y22: =1.5*J22 -> 0 | Z22: Lognormal | AA22: =0.9*K22 -> 32190.275 | AB22: =1.3*K22 -> 46497.063 | AC22: Lognormal | AD22: 0.1 | AE22: 1 | AF22: 0 | AG22: Truncated Normal
A23: 223 | B23: 2 | C23: Testing Building | D23: =REPT(" ", B23*2) & C23 -> Testing Building | W23: No Learning | X23: =0.9*$I23 -> 0 | Y23: =1.5*J23 -> 0 | Z23: Lognormal | AA23: =0.9*K23 -> 0 | AB23: =1.3*K23 -> 0 | AC23: Lognormal | AD23: 0.1 | AE23: 1 | AF23: 0 | AG23: Truncated Normal
A24: 224 | B24: =IF(ISNUMBER(A24), IF(AND(A24=INT(A24), MOD(A24, 10) = 0), 0, IF(AND(A24=INT(A24), LEN(A24)=2), 1, IF(AND(A24=INT(A24), LEN(A24)=3), 2, LEN(A24) - FIND(".", A24) + 2) ) ), "") -> 2 | C24: Warehouse | D24: =REPT(" ", B24*2) & C24 -> Warehouse | E24: standard | K24: 3842.71 | L24: $/m^2 | M24: MFG Warehouse Building Area | N24: 1 | O24: m^2 | P24: 1 | Q24: 2025 | R24: Lab and Mat and Equip | W24: No Learning | X24: =0.9*$I24 -> 0 | Y24: =1.5*J24 -> 0 | Z24: Lognormal | AA24: =0.9*K24 -> 3458.439 | AB24: =1.3*K24 -> 4995.523 | AC24: Lognormal | AD24: 0.1 | AE24: 1 | AF24: 0 | AG24: Truncated Normal
A25: 225 | B25: =IF(ISNUMBER(A25), IF(AND(A25=INT(A25), MOD(A25, 10) = 0), 0, IF(AND(A25=INT(A25), LEN(A25)=2), 1, IF(AND(A25=INT(A25), LEN(A25)=3), 2, LEN(A25) - FIND(".", A25) + 2) ) ), "") -> 2 | C25: Administrative Building | D25: =REPT(" ", B25*2) & C25 -> Administrative Building | E25: standard | K25: =0.7*1968*(3.2808^2) -> 14828.002 | L25: $/m^2 | M25: MFG Administration Building Area | N25: 1 | O25: m^2 | P25: 1 | Q25: 2025 | R25: Lab and Mat and Equip | S25: 100 value from MC30 Cost Estimation of Microreactor Facilities Inital Draft 5-6-2026.pdf, less 30% [temporary, want to add scaling equation] | W25: No Learning | X25: =0.9*$I25 -> 0 | Y25: =1.5*J25 -> 0 | Z25: Lognormal | AA25: =0.9*K25 -> 13345.202 | AB25: =1.3*K25 -> 19276.403 | AC25: Lognormal | AD25: 0.1 | AE25: 1 | AF25: 0 | AG25: Truncated Normal
A26: 23 | B26: =IF(ISNUMBER(A26), IF(AND(A26=INT(A26), MOD(A26, 10) = 0), 0, IF(AND(A26=INT(A26), LEN(A26)=2), 1, IF(AND(A26=INT(A26), LEN(A26)=3), 2, LEN(A26) - FIND(".", A26) + 2) ) ), "") -> 1 | C26: Equipment | D26: =REPT(" ", B26*2) & C26 -> Equipment
A27: 23.5 | B27: 2 | C27: Local Integrated Control Rooms | D27: =REPT(" ", B27*2) & C27 -> Local Integrated Control Rooms | E27: standard | F27: MFG Testing Line Count | G27: 1 | J27: 8500000 | Q27: 2023 | R27: Lab and Equip | S27: Shirvan et al., 2023 | T27: Shirvan et al,. (2023). UO2-fueled microreactors: Near-term solutions to emerging marktets. Nuclear Engineering and Design. | U27: https://doi.org/10.1016/j.nucengdes.2023.112470 | V27: Cost based on FOAK Digital I&C with 2-out-of-4 voting logic | W27: Factory Other | X27: =0.9*$H27 -> 0 | Y27: =1.5*J27 -> 12750000 | Z27: Lognormal | AA27: =0.9*K27 -> 0 | AB27: =1.3*K27 -> 0 | AC27: Lognormal | AD27: 0.1 | AE27: 1 | AF27: 0 | AG27: Truncated Normal
A28: 28 | B28: =IF(ISNUMBER(A28), IF(AND(A28=INT(A28), MOD(A28, 10) = 0), 0, IF(AND(A28=INT(A28), LEN(A28)=2), 1, IF(AND(A28=INT(A28), LEN(A28)=3), 2, LEN(A28) - FIND(".", A28) + 2) ) ), "") -> 1 | C28: Auxiliary Infrastructure Equipment | D28: =REPT(" ", B28*2) & C28 -> Auxiliary Infrastructure Equipment
A29: 281 | B29: =IF(ISNUMBER(A29), IF(AND(A29=INT(A29), MOD(A29, 10) = 0), 0, IF(AND(A29=INT(A29), LEN(A29)=2), 1, IF(AND(A29=INT(A29), LEN(A29)=3), 2, LEN(A29) - FIND(".", A29) + 2) ) ), "") -> 2 | C29: Emergency Power | D29: =REPT(" ", B29*2) & C29 -> Emergency Power | E29: standard | K29: =(1450000*5+1500000)/2.5 -> 3500000 | L29: $/MWe | M29: MFG Emergency Generator Power | N29: 1 | O29: MWe | P29: 1 | Q29: 2025 | R29: Equipment | S29: 2.5 MW generator cost from Central States Generators, nuclear multiple of 5, and guess for pad and connection to building (pad and connection have been requested with cost estimators)
A30: 283 | B30: =IF(ISNUMBER(A30), IF(AND(A30=INT(A30), MOD(A30, 10) = 0), 0, IF(AND(A30=INT(A30), LEN(A30)=2), 1, IF(AND(A30=INT(A30), LEN(A30)=3), 2, LEN(A30) - FIND(".", A30) + 2) ) ), "") -> 2 | C30: Fire Station | D30: =REPT(" ", B30*2) & C30 -> Fire Station | E30: standard | F30: MFG Fire Station Count | G30: 1 | J30: =0.7*20776500 -> 14543550 | Q30: 2025 | R30: Lab and Mat and Equip | S30: 100 value from MC30 Cost Estimation of Microreactor Facilities Inital Draft 5-6-2026.pdf, less 30% [temporary, want to add scaling equation] | W30: No Learning | X30: =0.9*$I30 -> 0 | Y30: =1.5*J30 -> 21815325 | Z30: Lognormal | AA30: =0.9*K30 -> 0 | AB30: =1.3*K30 -> 0 | AC30: Lognormal | AD30: 0.1 | AE30: 1 | AF30: 0 | AG30: Truncated Normal
A31: 284 | B31: =IF(ISNUMBER(A31), IF(AND(A31=INT(A31), MOD(A31, 10) = 0), 0, IF(AND(A31=INT(A31), LEN(A31)=2), 1, IF(AND(A31=INT(A31), LEN(A31)=3), 2, LEN(A31) - FIND(".", A31) + 2) ) ), "") -> 2 | C31: Security Building | D31: =REPT(" ", B31*2) & C31 -> Security Building | E31: standard | K31: =0.7*2548*(3.2808^2) -> 19198.044 | L31: $/m^2 | M31: MFG Security Building Area | N31: 1 | O31: m^2 | P31: 1 | Q31: 2025 | R31: Lab and Mat and Equip | S31: 100 value from MC30 Cost Estimation of Microreactor Facilities Inital Draft 5-6-2026.pdf, less 30% [temporary, want to add scaling equation] | W31: No Learning | X31: =0.9*$I31 -> 0 | Y31: =1.5*J31 -> 0 | Z31: Lognormal | AA31: =0.9*K31 -> 17278.239 | AB31: =1.3*K31 -> 24957.457 | AC31: Lognormal | AD31: 0.1 | AE31: 1 | AF31: 0 | AG31: Truncated Normal
A32: 285 | B32: =IF(ISNUMBER(A32), IF(AND(A32=INT(A32), MOD(A32, 10) = 0), 0, IF(AND(A32=INT(A32), LEN(A32)=2), 1, IF(AND(A32=INT(A32), LEN(A32)=3), 2, LEN(A32) - FIND(".", A32) + 2) ) ), "") -> 2 | C32: Switchyard | D32: =REPT(" ", B32*2) & C32 -> Switchyard | E32: standard | K32: =0.7*221450153/N32 -> 516717.02 | L32: $/MWe | M32: MFG Switchyard Rating | N32: 300 | O32: MWe | P32: 0.9968 | Q32: 2025 | R32: Lab and Mat and Equip | S32: Scaling relationship created from MC30 Cost Estimation of Microreactor Facilities Inital Draft 5-6-2026.pdf, less 30% | W32: No Learning | X32: =0.9*$I32 -> 0 | Y32: =1.5*J32 -> 0 | Z32: Lognormal | AA32: =0.9*K32 -> 465045.32 | AB32: =1.3*K32 -> 671732.13 | AC32: Lognormal | AD32: 0.1 | AE32: 1 | AF32: 0 | AG32: Truncated Normal
A33: 286 | B33: =IF(ISNUMBER(A33), IF(AND(A33=INT(A33), MOD(A33, 10) = 0), 0, IF(AND(A33=INT(A33), LEN(A33)=2), 1, IF(AND(A33=INT(A33), LEN(A33)=3), 2, LEN(A33) - FIND(".", A33) + 2) ) ), "") -> 2 | C33: Onsite Transport Equipment | D33: =REPT(" ", B33*2) & C33 -> Onsite Transport Equipment
A34: 286.1 | B34: =IF(ISNUMBER(A34), IF(AND(A34=INT(A34), MOD(A34, 10) = 0), 0, IF(AND(A34=INT(A34), LEN(A34)=2), 1, IF(AND(A34=INT(A34), LEN(A34)=3), 2, LEN(A34) - FIND(".", A34) + 2) ) ), "") -> 3 | C34: Local Reactor Transport Vehicles | D34: =REPT(" ", B34*2) & C34 -> Local Reactor Transport Vehicles | E34: standard | F34: MFG Local Transport Vehicle Count | G34: 1 | J34: 938000 | Q34: 2023 | R34: Equipment | S34: Lallemant report, Table 9, Considered price for 200 MT LTV | T34: Lallemant, Lucas. 2023 | W34: No Learning | X34: =0.9*$J34 -> 844200 | Y34: =1.5*J34 -> 1407000 | Z34: Lognormal | AA34: =0.9*K34 -> 0 | AB34: =1.3*K34 -> 0 | AC34: Lognormal | AD34: 0.1 | AE34: 1 | AF34: 0 | AG34: Truncated Normal
A35: 286.2 | B35: =IF(ISNUMBER(A35), IF(AND(A35=INT(A35), MOD(A35, 10) = 0), 0, IF(AND(A35=INT(A35), LEN(A35)=2), 1, IF(AND(A35=INT(A35), LEN(A35)=3), 2, LEN(A35) - FIND(".", A35) + 2) ) ), "") -> 3 | C35: Utility Vehicles | D35: =REPT(" ", B35*2) & C35 -> Utility Vehicles | E35: standard | F35: MFG Utility Vehicle Count | G35: 1 | J35: 50000 | Q35: 2024 | R35: Equipment | S35: assumption | W35: No Learning | X35: =0.9*$J35 -> 45000 | Y35: =1.5*J35 -> 75000 | Z35: Lognormal | AA35: =0.9*K35 -> 0 | AB35: =1.3*K35 -> 0 | AC35: Lognormal | AD35: 0.1 | AE35: 1 | AF35: 0 | AG35: Truncated Normal
A36: 288 | B36: =IF(ISNUMBER(A36), IF(AND(A36=INT(A36), MOD(A36, 10) = 0), 0, IF(AND(A36=INT(A36), LEN(A36)=2), 1, IF(AND(A36=INT(A36), LEN(A36)=3), 2, LEN(A36) - FIND(".", A36) + 2) ) ), "") -> 2 | C36: Dispered Infrastructure | D36: =REPT(" ", B36*2) & C36 -> Dispered Infrastructure | S36: assumption, guess
A37: 288.1 | B37: 3 | C37: Communication | D37: =REPT(" ", B37*2) & C37 -> Communication | E37: standard | K37: =12575250/N37 -> 11774.579 | L37: $/acres | M37: Manufacturing Campus Area | N37: 1068 | O37: acres | Q37: 2025 | R37: Equipment | S37: [to become a scaling relationship] MC30 Cost Estimation of Microreactor Facilities Inital Draft 5-6-2026.pdf
A38: 288.2 | B38: 3 | C38: Security Cameras | D38: =REPT(" ", B38*2) & C38 -> Security Cameras | E38: standard | F38: MFG Security Camera Count | G38: 1 | J38: 28431 | Q38: 2025 | R38: Equipment | S38: MC30 Cost Estimation of Microreactor Facilities Inital Draft 5-6-2026.pdf
A39: 288.3 | B39: 3 | C39: Motion Detectors | D39: =REPT(" ", B39*2) & C39 -> Motion Detectors | E39: standard | F39: MFG Motion Detector Count | G39: 1 | J39: 24057 | Q39: 2025 | R39: Equipment | S39: MC30 Cost Estimation of Microreactor Facilities Inital Draft 5-6-2026.pdf
A40: 288.4 | B40: 3 | C40: Guard Station | D40: =REPT(" ", B40*2) & C40 -> Guard Station | E40: standard | F40: MFG Guard Station Count | G40: 1 | J40: 6774250 | Q40: 2025 | R40: Equipment | S40: MC30 Cost Estimation of Microreactor Facilities Inital Draft 5-6-2026.pdf
...

Sheet Servicing Campus Database
A1: Account | B1: Level | C1: Account Name | D1: Account Title | E1: Standard Cost Equation? | F1: Count Scaling Variable | G1: Count per Variable | H1: Optional Variable | I1: Optional Value | J1: Fixed Cost ($) | K1: Unit Cost | L1: Unit Cost (units) | M1: Scaling Variable | N1: Scaling Variable Ref Value | O1: Units | P1: Exponent | Q1: Dollar Year | R1: Type | S1: Source | T1: Ref | U1: Link | V1: Notes | W1: FOAK to NOAK Multiplier Type | X1: Fixed Cost Low End | Y1: Fixed Cost High End | Z1: Fixed Cost Distribution | AA1: Unit Cost Low End | AB1: Unit Cost High End | AC1: Unit Cost Distribution | AD1: Exponent std | AE1: Exponent Max | AF1: Exponent Min | AG1: Exponent Distribution
A2: 10 | B2: =IF(ISNUMBER(A2), IF(AND(A2=INT(A2), MOD(A2, 10) = 0), 0, IF(AND(A2=INT(A2), LEN(A2)=2), 1, IF(AND(A2=INT(A2), LEN(A2)=3), 2, LEN(A2) - FIND(".", A2) + 2) ) ), "") -> 0 | C2: Capitalized Pre-Construction Costs | D2: =REPT(" ", B2*2) & C2 -> Capitalized Pre-Construction Costs
